Workbook

Sheet Part 1
B1: CUB | H1: PAGEIND | N1: INOXWIND | T1: DATAPATTNS | Z1: POLICYBZR | AF1: DALBHARAT | AL1: DLF | AR1: OIL | AY1: NIFTY 50 INDEX | BF1: PORTFOLIO | BL1: WEIGHTS OF INDIVIDUAL STOCK IN THE PORTFOLIO
A2: DATE | B2: DAILY RETURNS(%) | C2: WEEKDAY | D2: WEEKLY RETURN(%) | E2: MONTH NUM | F2: MONTHLY RETURN(%) | H2: DAILY RETURNS(%) | I2: WEEKDAY | J2: WEEKLY RETURN(%) | K2: MONTH NUM | L2: MONTHLY RETURN(%) | N2: DAILY RETURNS(%) | O2: WEEKDAY | P2: WEEKLY RETURN(%) | Q2: MONTH NUM | R2: MONTHLY RETURN(%) | T2: DAILY RETURNS(%) | U2: WEEKDAY | V2: WEEKLY RETURN(%) | W2: MONTH NUM | X2: MONTHLY RETURN(%) | Z2: DAILY RETURNS(%) | AA2: WEEKDAY | AB2: WEEKLY RETURN(%) | AC2: MONTH NUM | AD2: MONTHLY RETURN(%) | AF2: DAILY RETURNS(%) | AG2: WEEKDAY | AH2: WEEKLY RETURN(%) | AI2: MONTH NUMBER | AJ2: MONTHLY RETURNS(%) | AL2: DAILY RETURNS(%) | AM2: WEEKDAY | AN2: WEEKLY RETURN(%) | AO2: MONTH NUMBER | AP2: MONTHLY RETURN(%) | AR2: DAILY RETURNS(%) | AS2: WEEKDAY | AT2: WEEKLY RETURN(%) | AU2: MONTH NUMBER | AV2: MONTHLY RETURN(%) | BL2: CUB | BM2: PAGEIND | BN2: INOXWIND | BO2: DATAPATTNS | BP2: POLICYBZR | BQ2: DALBHARAT | BR2: DLF | BS2: OIL | BV2: On the basis of daily returns | BW2: CUB | BX2: PAGEIND | BY2: INOXWIND | BZ2: DATAPATTNS | CA2: POLICYBZR | CB2: DALBHARAT | CC2: DLF | CD2: OIL
A3: 44742 | C3: 4 | I3: 4 | O3: 4 | U3: 4 | AA3: 4 | AG3: 4 | AM3: 4 | AS3: 4 | AY3: DAILY VARIATION(%)-NIFTY 50 | AZ3: WEEKLY VARIATION(%)-NIFTY 50 | BA3: MONTHLY VARIATION(%)-NIFTY 50 | BF3: DAILY RETURNS(%) | BG3: WEEKLY RETURNS(%) | BH3: MONTHLY RETURNS(%) | BL3: 0.15 | BM3: 0.1 | BN3: 0.12 | BO3: 0.13 | BP3: 0.1 | BQ3: 0.15 | BR3: 0.12 | BS3: 0.13 | BV3: Correlation(Stock vs NIFTY 50) | BW3: =CORREL(B4:B497,AY4:AY497) -> 0.44466894 | BX3: =CORREL(H4:H497,AY4:AY497) -> 0.26450938 | BY3: =CORREL(N4:N497,AY4:AY497) -> 0.18621438 | BZ3: =CORREL(T4:T497,AY4:AY497) -> 0.27667805 | CA3: =CORREL(Z4:Z497,AY4:AY497) -> 0.26421572 | CB3: =CORREL(AF4:AF497,AY4:AY497) -> 0.49556188 | CC3: =CORREL(AL4:AL497,AY4:AY497) -> 0.58882038 | CD3: =CORREL(AR4:AR497,AY4:AY497) -> 0.29604095
A4: 44743 | B4: 1.8038331 | C4: 5 | E4: 44743 | F4: 18.752307 | H4: 3.0107179 | I4: 5 | K4: 44743 | L4: 18.11977 | N4: -1.958307 | O4: 5 | Q4: 44743 | R4: 14.43299 | T4: -0.67135051 | U4: 5 | W4: 44743 | X4: 21.997799 | Z4: 2.635483 | AA4: 5 | AC4: 44743 | AD4: -20.372417 | AF4: 3.3654033 | AG4: 5 | AI4: 44743 | AJ4: 20.559973 | AL4: 3.3418612 | AM4: 5 | AO4: 44743 | AP4: 19.4337 | AR4: -14.970179 | AS4: 5 | AU4: 44743 | AV4: -11.152677 | AY4: -0.17870439 | BA4: 8.927092 | BF4: -0.52736676 | BH4: 11.145446
A5: 44746 | B5: 2.1410114 | C5: 1 | H5: 1.6357388 | I5: 1 | N5: 3.0927835 | O5: 1 | T5: 0.80163471 | U5: 1 | Z5: -0.56967945 | AA5: 1 | AF5: -0.68206655 | AG5: 1 | AL5: 0.4951261 | AM5: 1 | AR5: -5.7049334 | AS5: 1 | AY5: 0.52882006 | BF5: 0.11856799
A6: 44747 | B6: 1.4817492 | C6: 2 | H6: 0.70304809 | I6: 2 | N6: -2.3125 | O6: 2 | T6: 2.3935755 | U6: 2 | Z6: 0.19668206 | AA6: 2 | AF6: -1.2027622 | AG6: 2 | AL6: -0.81601232 | AM6: 2 | AR6: -5.4797917 | AS6: 2 | AY6: -0.15471714 | BF6: -0.64480851 | BV6: On the basis of weekly returns | BW6: CUB | BX6: PAGEIND | BY6: INOXWIND | BZ6: DATAPATTNS | CA6: POLICYBZR | CB6: DALBHARAT | CC6: DLF | CD6: OIL
A7: 44748 | B7: 0.64102564 | C7: 3 | H7: 2.8871323 | I7: 3 | N7: 0.44785669 | O7: 3 | T7: 5.7184192 | U7: 3 | Z7: -2.2702057 | AA7: 3 | AF7: 6.1100657 | AG7: 3 | AL7: 2.3284694 | AM7: 3 | AR7: -8.6044071 | AS7: 3 | AY7: 1.1318177 | BF7: 1.0323371 | BL7: Portfolio Value | BM7: 1000000 | BV7: Correlation(Stock vs NIFTY 50) | BW7: =CORREL(D4:D497,AZ4:AZ497) -> 0.40139814 | BX7: =CORREL(J4:J497,AZ4:AZ497) -> 0.28008765 | BY7: =CORREL(P4:P497,AZ4:AZ497) -> 0.37197175 | BZ7: =CORREL(V4:V497,AZ4:AZ497) -> 0.34040083 | CA7: =CORREL(AB4:AB497,AZ4:AZ497) -> 0.21844661 | CB7: =CORREL(AH4:AH497,AZ4:AZ497) -> 0.53885662 | CC7: =CORREL(AN4:AN497,AZ4:AZ497) -> 0.60912346 | CD7: =CORREL(AT4:AT497,AY4:AY497) -> -0.024498016
A8: 44749 | B8: 2.5831564 | C8: 4 | D8: 8.944006 | H8: 1.0176517 | I8: 4 | J8: 9.5796248 | N8: 3.2484076 | O8: 4 | P8: 2.4005054 | T8: 0.14405071 | U8: 4 | V8: 8.540203 | Z8: -0.4803074 | AA8: 4 | AB8: -0.54978619 | AF8: 5.1863916 | AG8: 4 | AH8: 13.204534 | AL8: 2.2148058 | AM8: 4 | AN8: 7.739047 | AR8: 1.3490241 | AS8: 4 | AT8: -29.801193 | AY8: 0.89494553 | AZ8: 2.2347555 | BF8: 2.068852 | BG8: 2.6788246 | BL8: Company | BM8: Total Market Cap (₹ Cr.) | BN8: Industry | BO8: Weight Assigned | BP8: Investment Amount (₹) | BQ8: Daily Volatility
A9: 44750 | B9: -0.068989307 | C9: 5 | H9: -0.99649432 | I9: 5 | N9: 1.1104257 | O9: 5 | T9: 1.9490794 | U9: 5 | Z9: -1.009126 | AA9: 5 | AF9: -1.3419124 | AG9: 5 | AL9: 1.0388839 | AM9: 5 | AR9: 4.3330501 | AS9: 5 | AY9: 0.54360964 | BF9: 0.6623967 | BL9: CUB | BM9: 13399.5 | BN9: Private Sector Bank | BO9: 0.15 | BP9: =BO9*1000000 -> 150000 | BQ9: 2.05
A10: 44753 | B10: 2.9340697 | C10: 1 | H10: -0.40527175 | I10: 1 | N10: -0.12202563 | O10: 1 | T10: 3.2592593 | U10: 1 | Z10: -1.0105487 | AA10: 1 | AF10: 1.1753217 | AG10: 1 | AL10: 1.6891892 | AM10: 1 | AR10: 1.3029316 | AS10: 1 | AY10: -0.028359 | BF10: 1.2559711 | BL10: PAGEIND | BM10: 50359.74 | BN10: Garments & Apparels | BO10: 0.1 | BP10: =BO10*1000000 -> 100000 | BQ10: 1.49 | BV10: On the basis of monthly returns | BW10: CUB | BX10: PAGEIND | BY10: INOXWIND | BZ10: DATAPATTNS | CA10: POLICYBZR | CB10: DALBHARAT | CC10: DLF | CD10: OIL
A11: 44754 | B11: -0.46948357 | C11: 2 | H11: -0.71487658 | I11: 2 | N11: -2.3824068 | O11: 2 | T11: -1.9471203 | U11: 2 | Z11: 0.34028835 | AA11: 2 | AF11: -0.85143054 | AG11: 2 | AL11: 0.18777986 | AM11: 2 | AR11: -1.6881029 | AS11: 2 | AY11: -0.9724963 | BF11: -0.97153019 | BL11: INOXWIND | BM11: 28650.87 | BN11: Heavy Electrical Equipment | BO11: 0.12 | BP11: =BO11*1000000 -> 120000 | BQ11: 3.46 | BV11: Correlation(Stock vs NIFTY 50) | BW11: =CORREL(F4:F497,BA4:BA497) -> 0.60061112 | BX11: =CORREL(L4:L497,BA4:BA497) -> 0.55434405 | BY11: =CORREL(R4:R497,BA4:BA497) -> 0.42594815 | BZ11: =CORREL(X4:X497,BA4:BA497) -> 0.29513966 | CA11: =CORREL(AD4:AD497,BA4:BA497) -> -0.22921819 | CB11: =CORREL(AJ4:AJ497,BA4:BA497) -> 0.41424883 | CC11: =CORREL(AP4:AP497,BA4:BA497) -> 0.70765904 | CD11: =CORREL(AV4:AV497,BA4:BA497) -> 0.03744721
A12: 44755 | B12: 1.5498652 | C12: 3 | H12: 0.95349493 | I12: 3 | N12: -0.8135169 | O12: 3 | T12: 0.02090301 | U12: 3 | Z12: -0.09817046 | AA12: 3 | AF12: 2.7118173 | AG12: 3 | AL12: 0.18742791 | AM12: 3 | AR12: 1.0902153 | AS12: 3 | AY12: -0.57073289 | BF12: 0.79409953 | BL12: DATAPATTNS | BM12: 13402 | BN12: Aerospace & Defense | BO12: 0.13 | BP12: =BO12*1000000 -> 130000 | BQ12: 3.06
A13: 44756 | B13: -0.2986065 | C13: 4 | D13: 3.6564333 | H13: 0.42448569 | I13: 4 | J13: -0.74964273 | N13: 0.3785489 | O13: 4 | P13: -1.8507094 | T13: 1.6858238 | U13: 4 | V13: 4.9841772 | Z13: -2.6442737 | AA13: 4 | AB13: -4.3699544 | AF13: -2.5082084 | AG13: 4 | AH13: -0.89804907 | AL13: 0.31659232 | AM13: 4 | AN13: 3.4579994 | AR13: -4.0172553 | AS13: 4 | AT13: 0.82129708 | AY13: -0.17536553 | AZ13: -1.2040613 | BF13: -0.86267019 | BG13: 0.84938437 | BL13: POLICYBZR | BM13: 79388.22 | BN13: Financial Technology | BO13: 0.1 | BP13: =BO13*1000000 -> 100000 | BQ13: 2.65
A14: 44757 | B14: 0.86522463 | C14: 5 | H14: 1.5661215 | I14: 5 | N14: -1.9484601 | O14: 5 | T14: -1.8496951 | U14: 5 | Z14: -3.8080382 | AA14: 5 | AF14: 0.57287688 | AG14: 5 | AL14: 1.4632047 | AM14: 5 | AR14: 2.3876404 | AS14: 5 | AY14: 0.69359701 | BF14: 0.0032258037 | BL14: DALBHARAT | BM14: 33664.8 | BN14: Construction Materials | BO14: 0.15 | BP14: =BO14*1000000 -> 150000 | BQ14: 1.8
A15: 44760 | B15: 1.682613 | C15: 1 | H15: -0.66195612 | I15: 1 | N15: 2.5 | O15: 1 | T15: -0.10469742 | U15: 1 | Z15: 0.15262806 | AA15: 1 | AF15: 2.9033038 | AG15: 1 | AL15: -0.12724445 | AM15: 1 | AR15: 1.2620027 | AS15: 1 | AY15: 1.4287317 | BF15: 1.0721351 | BL15: DLF | BM15: 199064.84 | BN15: Realty | BO15: 0.12 | BP15: =BO15*1000000 -> 120000 | BQ15: 2.14
A16: 44761 | B16: 2.5308241 | C16: 2 | H16: -0.7350005 | I16: 2 | N16: 1.6260163 | O16: 2 | T16: 4.1154276 | U16: 2 | Z16: 0.46671112 | AA16: 2 | AF16: 1.6304348 | AG16: 2 | AL16: 1.882786 | AM16: 2 | AR16: 1.1108101 | AS16: 2 | AY16: 0.38117763 | BF16: 1.6978271 | BL16: OIL | BM16: 84559.21 | BN16: Oil Exploration & Production | BO16: 0.13 | BP16: =BO16*1000000 -> 130000 | BQ16: 2.88
A17: 44762 | B17: -0.15822785 | C17: 3 | H17: 0.54844649 | I17: 3 | N17: 0.86153846 | O17: 3 | T17: 0.51674384 | U17: 3 | Z17: -0.58778915 | AA17: 3 | AF17: -0.11883541 | AG17: 3 | AL17: -0.95873281 | AM17: 3 | AR17: 5.8145766 | AS17: 3 | AY17: 1.10339 | BF17: 0.76591458
A18: 44763 | B18: 1.4896989 | C18: 4 | D18: 6.5557404 | H18: 2.5816762 | I18: 4 | J18: 3.3012967 | N18: -0.18303844 | O18: 4 | P18: 2.8284098 | T18: 1.1416745 | U18: 4 | V18: 3.781599 | Z18: 0.54358192 | AA18: 4 | AB18: -3.2574784 | AF18: 1.7747373 | AG18: 4 | AH18: 6.9196584 | AL18: 1.1784512 | AM18: 4 | AN18: 3.4571797 | AR18: 1.6713092 | AS18: 4 | AT18: 12.780899 | AY18: 0.5108696 | AZ18: 4.1822865 | BF18: 1.2873286 | BG18: 4.9338718
A19: 44764 | B19: 2.467208 | C19: 5 | H19: 0.47854365 | I19: 5 | N19: -0.85574572 | O19: 5 | T19: -0.88454683 | U19: 5 | Z19: -1.3373803 | AA19: 5 | AF19: 3.6174704 | AG19: 5 | AL19: -0.12479201 | AM19: 5 | AR19: -2.5902864 | AS19: 5 | AY19: 0.6877343 | BF19: 0.25742524
A20: 44767 | B20: -1.5239256 | C20: 1 | H20: 0.60506214 | I20: 1 | N20: -1.541307 | O20: 1 | T20: -0.97236097 | U20: 1 | Z20: -3.9223226 | AA20: 1 | AF20: -2.8643956 | AG20: 1 | AL20: -0.77745384 | AM20: 1 | AR20: -4.6279724 | AS20: 1 | AY20: -0.52902458 | BF20: -1.9962689
A21: 44768 | B21: 0.40235221 | C21: 2 | H21: 1.2651041 | I21: 2 | N21: 9.6430808 | O21: 2 | T21: -1.7687807 | U21: 2 | Z21: -5.573344 | AA21: 2 | AF21: -0.98725601 | AG21: 2 | AL21: 0.96544004 | AM21: 2 | AR21: -1.0991957 | AS21: 2 | AY21: -0.88479346 | BF21: 0.38162601
A22: 44769 | B22: -0.18495684 | C22: 3 | H22: 2.3021438 | I22: 3 | N22: -3.2552827 | O22: 3 | T22: 5.0732576 | U22: 3 | Z22: -2.9246583 | AA22: 3 | AF22: 2.7371371 | AG22: 3 | AL22: 2.1757206 | AM22: 3 | AR22: 1.3282732 | AS22: 3 | AY22: 0.95821061 | BF22: 1.0232271
A23: 44770 | B23: -0.46324892 | C23: 4 | D23: 0.6558401 | H23: 1.0647021 | I23: 4 | J23: 5.8369251 | N23: 2.7154664 | O23: 4 | P23: 6.3569682 | T23: -1.3357659 | U23: 4 | V23: -0.04620767 | Z23: 0.31655933 | AA23: 4 | AB23: -12.833159 | AF23: 0.56138793 | AG23: 4 | AH23: 2.9582724 | AL23: 3.621321 | AM23: 4 | AN23: 5.9345535 | AR23: -0.16051364 | AS23: 4 | AT23: -7.0485679 | AY23: 1.7293802 | AZ23: 1.9532979 | BF23: 0.71874513 | BG23: 0.39515523
A24: 44771 | B24: -0.18616196 | C24: 5 | H24: 2.3293307 | I24: 5 | N24: 2.0689655 | O24: 5 | T24: 2.5161802 | U24: 5 | Z24: 1.9042437 | AA24: 5 | AF24: 0.90519145 | AG24: 5 | AL24: 1.0340314 | AM24: 5 | AR24: 1.8220793 | AS24: 5 | AY24: 1.350593 | BF24: 1.4675452
A25: 44774 | B25: 0.15542431 | C25: 1 | E25: 44774 | F25: 11.700807 | H25: 0.71573261 | I25: 1 | K25: 44774 | L25: 3.6981846 | N25: 5.9684685 | O25: 1 | Q25: 44774 | R25: 18.756642 | T25: 2.7378728 | U25: 1 | W25: 44774 | X25: 33.834964 | Z25: 7.6775227 | AA25: 1 | AC25: 44774 | AD25: -0.22808409 | AF25: -0.83455756 | AG25: 1 | AI25: 44774 | AJ25: -3.1488369 | AL25: -0.44047156 | AM25: 1 | AO25: 44774 | AP25: 1.4964216 | AR25: 2.0263158 | AS25: 1 | AU25: 44774 | AV25: -0.54165592 | AY25: 1.0595486 | BA25: 2.4178131 | BF25: 2.0201597 | BH25: 8.3883317
A26: 44775 | B26: 1.3345748 | C26: 2 | H26: -0.47803051 | I26: 2 | N26: 3.8788523 | O26: 2 | T26: -5.8251818 | U26: 2 | Z26: 10.948036 | AA26: 2 | AF26: -0.24270315 | AG26: 2 | AL26: -1.977879 | AM26: 2 | AR26: -1.7539335 | AS26: 2 | AY26: 0.031141779 | BF26: 0.45361315
A27: 44776 | B27: -0.4287902 | C27: 3 | H27: -1.9798928 | I27: 3 | N27: 4.5524297 | O27: 3 | T27: 3.3024835 | U27: 3 | Z27: -0.70611369 | AA27: 3 | AF27: -2.2212392 | AG27: 3 | AL27: -1.1814682 | AM27: 3 | AR27: -0.57757942 | AS27: 3 | AY27: 0.24617407 | BF27: 0.092647844
A28: 44777 | B28: -1.6610274 | C28: 4 | D28: -0.80670183 | H28: 2.1015211 | I28: 4 | J28: 2.6511448 | N28: -0.048923679 | O28: 4 | P28: 17.413793 | T28: 3.0808895 | U28: 4 | V28: 5.6201294 | Z28: -1.0081916 | AA28: 4 | AB28: 19.662677 | AF28: 0.9403477 | AG28: 4 | AH28: -1.4792153 | AL28: -1.2358947 | AM28: 4 | AN28: -3.7696335 | AR28: -0.73937153 | AS28: 4 | AT28: 0.72347267 | AY28: -0.035368915 | AZ28: 2.6722427 | BF28: 0.15145013 | BG28: 4.3546217
A29: 44778 | B29: 0.75070378 | C29: 5 | H29: -1.6625635 | I29: 5 | N29: 1.9089574 | O29: 5 | T29: 2.5698743 | U29: 5 | Z29: 3.8919705 | AA29: 5 | AF29: 3.4862503 | AG29: 5 | AL29: 0.054406964 | AM29: 5 | AR29: 5.2407555 | AS29: 5 | AY29: 0.089172707 | BF29: 2.1094694
A30: 44781 | B30: 1.0866191 | C30: 1 | H30: 0.86182578 | I30: 1 | N30: -0.81652257 | O30: 1 | T30: 1.6093636 | U30: 1 | Z30: -2.4157549 | AA30: 1 | AF30: -0.80430613 | AG30: 1 | AL30: 0.67971724 | AM30: 1 | AR30: 0.075834176 | AS30: 1 | AY30: 0.73343871 | BF30: 0.089613092
A31: 44783 | B31: 8.5380835 | C31: 3 | H31: -0.49293501 | I31: 3 | N31: 5.9564165 | O31: 3 | T31: 0 | U31: 3 | Z31: 0.54713427 | AA31: 3 | AF31: -2.844134 | AG31: 3 | AL31: -0.48609236 | AM31: 3 | AR31: -5.5822177 | AS31: 3 | AY31: 0.05506388 | BF31: 0.79026295
A32: 44784 | B32: -0.87719298 | C32: 4 | D32: 7.7514611 | H32: 1.2889719 | I32: 4 | J32: 2.069033 | N32: 3.1078611 | O32: 4 | P32: 10.37182 | T32: -0.14398848 | U32: 4 | V32: 7.2768289 | Z32: 4.058876 | AA32: 4 | AB32: 5.0049509 | AF32: 0.35629454 | AG32: 4 | AH32: 1.0308279 | AL32: 1.0990502 | AM32: 4 | AN32: 0.094035465 | AR32: 0.56179775 | AS32: 4 | AT32: -0.73937153 | AY32: 0.70859294 | AZ32: 1.55767 | BF32: 1.0157946 | BG32: 4.1351385
A33: 44785 | B33: 1.0562375 | C33: 5 | H33: 0.25759471 | I33: 5 | N33: -0.66489362 | O33: 5 | T33: 0.76303773 | U33: 5 | Z33: -1.731676 | AA33: 5 | AF33: -0.22069407 | AG33: 5 | AL33: 0.093947121 | AM33: 5 | AR33: 1.2769354 | AS33: 5 | AY33: 0.22169998 | BF33: 0.17460631
A34: 44789 | B34: 0.70621469 | C34: 2 | H34: 1.102013 | I34: 2 | N34: -5.577867 | O34: 2 | T34: 2.5341363 | U34: 2 | Z34: 0.68917386 | AA34: 2 | AF34: 1.593153 | AG34: 2 | AL34: 1.6760526 | AM34: 2 | AR34: 0.18387182 | AS34: 2 | AY34: 0.71815416 | BF34: 0.40914716
A35: 44790 | B35: -0.28050491 | C35: 3 | H35: -0.37772613 | I35: 3 | N35: -0.14177694 | O35: 3 | T35: 0.50011631 | U35: 3 | Z35: -0.91838503 | AA35: 3 | AF35: 0.67522797 | AG35: 3 | AL35: 0.31649743 | AM35: 3 | AR35: -0.15731515 | AS35: 3 | AY35: 0.66759232 | BF35: -0.0048720488
A36: 44791 | B36: 0.61884669 | C36: 4 | D36: 1.2167516 | H36: 1.1127231 | I36: 4 | J36: 3.4192786 | N36: -0.8045433 | O36: 4 | P36: -4.2047532 | T36: 0.27195926 | U36: 4 | V36: 3.9656827 | Z36: -2.0286814 | AA36: 4 | AB36: -0.05352364 | AF36: 4.4849093 | AG36: 4 | AH36: 7.0103358 | AL36: 2.3136585 | AM36: 4 | AN36: 5.6037992 | AR36: 0.65651261 | AS36: 4 | AT36: 2.541466 | AY36: 0.068266994 | AZ36: 2.4052239 | BF36: 0.97576273 | BG36: 2.5844534
A37: 44792 | B37: -1.6773833 | C37: 5 | H37: -0.019883338 | I37: 5 | N37: 2.6717557 | O37: 5 | T37: -0.33469906 | U37: 5 | Z37: -1.0085684 | AA37: 5 | AF37: -3.0475733 | AG37: 5 | AL37: -3.9701914 | AM37: 5 | AR37: -1.2261936 | AS37: 5 | AY37: -1.1029432 | BF37: -1.170317
A38: 44795 | B38: -2.3599659 | C38: 1 | H38: -2.0685782 | I38: 1 | N38: -3.3457249 | O38: 1 | T38: -2.7560651 | U38: 1 | Z38: -5.4278244 | AA38: 1 | AF38: -3.8363963 | AG38: 1 | AL38: -2.3815895 | AM38: 1 | AR38: -2.4035922 | AS38: 1 | AY38: -1.5077329 | BF38: -3.0371277
A39: 44796 | B39: 4.1933605 | C39: 2 | H39: 2.3000388 | I39: 2 | N39: 0.72115385 | O39: 2 | T39: 0.3929741 | U39: 2 | Z39: -2.2881114 | AA39: 2 | AF39: 0.46650795 | AG39: 2 | AL39: 0.93201754 | AM39: 2 | AR39: 0.1082544 | AS39: 2 | AY39: 0.49626373 | BF39: 0.96371328
A40: 44797 | B40: -0.50307434 | C40: 3 | H40: -0.64589882 | I40: 3 | N40: 0.66825776 | O40: 3 | T40: 4.5074432 | U40: 3 | Z40: 0.048785247 | AA40: 3 | AF40: -0.57322189 | AG40: 3 | AL40: 1.0456274 | AM40: 3 | AR40: 3.2170857 | AS40: 3 | AY40: 0.15616555 | BF40: 0.98869918
...

Sheet Part 2
E462: CUB | U462: PAGEIND | AK462: INOXWIND/NTPC Ltd. | BA462: DATAPATTNS/BEL | BQ462: POLICYBZR-SBILIFE | CG462: DALBHARAT | CW462: DLF | DM462: OIL/BPCL
A464: DATE | B464: EXPIRY DATE | C464: CLOSE PRICE | E464: DATE | F464: EXPIRY DATE | G464: CLOSE PRICE | I464: daily ret | J464: weekday | K464: weekly ret | L464: monthnum | M464: month ret | N464: cub equity adj to futs dates | Q464: DATE | R464: EXPIRY DATE | S464: CLOSE PRICE | U464: DATE | V464: EXPIRY DATE | W464: CLOSE PRICE | Y464: daily ret | Z464: weekday | AA464: weekly ret | AB464: monthnum | AC464: month ret | AD464: pageind equity adj to futs dates | AG464: DATE | AH464: EXPIRY DATE | AI464: CLOSE PRICE | AK464: DATE | AL464: EXPIRY DATE | AM464: CLOSE PRICE | AO464: daily ret | AP464: weekday | AQ464: weekly ret | AR464: monthnum | AS464: month ret | AT464: inoxwind equity adj to futs dates | AW464: DATE | AX464: EXPIRY DATE | AY464: CLOSE PRICE | BA464: DATE | BB464: EXPIRY DATE | BC464: CLOSE PRICE | BE464: daily ret | BF464: weekday | BG464: weekly ret | BH464: monthnum | BI464: month ret | BJ464: datapattns equity adj to futs dates | BM464: DATE | BN464: EXPIRY DATE | BO464: CLOSE PRICE | BQ464: DATE | BR464: EXPIRY DATE | BS464: CLOSE PRICE | BU464: daily ret | BV464: weekday | BW464: weekly ret | BX464: monthnum | BY464: month ret | BZ464: policybzr equity adj to futs dates | CC464: DATE | CD464: EXPIRY DATE | CE464: CLOSE PRICE | CG464: DATE | CH464: EXPIRY DATE | CI464: CLOSE PRICE | CK464: daily ret | CL464: weekday | CM464: weekly ret | CN464: monthnum | CO464: month ret | CP464: dalbharat equity adj to futs dates | CS464: DATE | CT464: EXPIRY DATE | CU464: CLOSE PRICE | CW464: DATE | CX464: EXPIRY DATE | CY464: CLOSE PRICE | DA464: daily ret | DB464: weekday | DC464: weekly ret | DD464: monthnum | DE464: month ret | DF464: dlf equity adj to futs dates | DI464: DATE | DJ464: EXPIRY DATE | DK464: CLOSE PRICE | DM464: DATE | DN464: EXPIRY DATE | DO464: CLOSE PRICE | DQ464: daily ret | DR464: weekday | DS464: weekly ret | DT464: monthnum | DU464: month ret | DV464: oil pf adj to futs
N465: DAILY RETURNS(%) | O465: WEEKLY RETURN(%) | P465: MONTHLY RETURN(%) | AD465: DAILY RETURNS(%) | AE465: WEEKLY RETURN(%) | AF465: MONTHLY RETURN(%) | AT465: DAILY RETURNS(%) | AU465: WEEKLY RETURN(%) | AV465: MONTHLY RETURN(%) | BJ465: DAILY RETURNS(%) | BK465: WEEKLY RETURN(%) | BL465: MONTHLY RETURN(%) | BZ465: DAILY RETURNS(%) | CA465: WEEKLY RETURN(%) | CB465: MONTHLY RETURN(%) | CP465: DAILY RETURNS(%) | CQ465: WEEKLY RETURN(%) | CR465: MONTHLY RETURNS(%) | DF465: DAILY RETURNS(%) | DG465: WEEKLY RETURN(%) | DH465: MONTHLY RETURN(%) | DV465: DAILY RETURNS(%) | DW465: WEEKLY RETURN(%) | DX465: MONTHLY RETURN(%)
A466: 45470 | B466: 45470 | C466: 167.35 | E466: {=INDEX($A$466:$A$918, ROWS($A$466:$A$918) - ROW() + ROW($A$466))} -> 44742 | F466: {=INDEX($B$466:$B$918, ROWS($B$466:$B$918) - ROW() + ROW($B$466))} -> 44742 | G466: {=INDEX($C$466:$C$918, ROWS($C$466:$C$918) - ROW() + ROW($C$466))} -> 133.3 | J466: =WEEKDAY(E466, 2) -> 4 | Q466: 45470 | R466: 45470 | S466: 40145 | U466: {=INDEX($Q$466:$Q$918, ROWS($Q$466:$Q$918) - ROW() + ROW($Q$466))} -> 44742 | V466: {=INDEX($R$466:$R$918, ROWS($R$466:$R$918) - ROW() + ROW($R$466))} -> 44742 | W466: {=INDEX($S$466:$S$918, ROWS($S$466:$S$918) - ROW() + ROW($S$466))} -> 40178.95 | Z466: =WEEKDAY(U466, 2) -> 4 | AG466: 45470 | AH466: 45470 | AI466: 376 | AK466: {=INDEX($AG$466:$AG$918, ROWS($AG$466:$AG$918) - ROW() + ROW($AG$466))} -> 44742 | AL466: {=INDEX($AH$466:$AH$918, ROWS($AH$466:$AH$918) - ROW() + ROW($AH$466))} -> 44742 | AM466: {=INDEX($AI$466:$AI$918, ROWS($AI$466:$AI$918) - ROW() + ROW($AI$466))} -> 142.55 | AP466: =WEEKDAY(AK466, 2) -> 4 | AW466: 45470 | AX466: 45470 | AY466: 304.5 | BA466: {=INDEX($AW$466:$AW$918, ROWS($AW$466:$AW$918) - ROW() + ROW($AW$466))} -> 44742 | BB466: {=INDEX($AX$466:$AX$918, ROWS($AX$466:$AX$918) - ROW() + ROW($AX$466))} -> 44742 | BC466: {=INDEX($AY$466:$AY$918, ROWS($AY$466:$AY$918) - ROW() + ROW($AY$466))} -> 233.55 | BF466: =WEEKDAY(BA466, 2) -> 4 | BM466: 45470 | BN466: 45470 | BO466: 1461.45 | BQ466: {=INDEX($AW$466:$AW$918, ROWS($AW$466:$AW$918) - ROW() + ROW($AW$466))} -> 44742 | BR466: {=INDEX($AX$466:$AX$918, ROWS($AX$466:$AX$918) - ROW() + ROW($AX$466))} -> 44742 | BS466: {=INDEX($BO$466:$BO$918, ROWS($BO$466:$BO$918) - ROW() + ROW($BO$466))} -> 1086.1 | BV466: =WEEKDAY(BQ466, 2) -> 4 | CC466: 45470 | CD466: 45470 | CE466: 1792.3 | CG466: {=INDEX($AW$466:$AW$918, ROWS($AW$466:$AW$918) - ROW() + ROW($AW$466))} -> 44742 | CH466: {=INDEX($AX$466:$AX$918, ROWS($AX$466:$AX$918) - ROW() + ROW($AX$466))} -> 44742 | CI466: {=INDEX($CE$466:$CE$918, ROWS($CE$466:$CE$918) - ROW() + ROW($CE$466))} -> 1282.35 | CL466: =WEEKDAY(CG466, 2) -> 4 | CS466: 45470 | CT466: 45470 | CU466: 817.2 | CW466: {=INDEX($AW$466:$AW$918, ROWS($AW$466:$AW$918) - ROW() + ROW($AW$466))} -> 44742 | CX466: {=INDEX($AX$466:$AX$918, ROWS($AX$466:$AX$918) - ROW() + ROW($AX$466))} -> 44742 | CY466: {=INDEX($CU$466:$CU$918, ROWS($CU$466:$CU$918) - ROW() + ROW($CU$466))} -> 313.5 | DB466: =WEEKDAY(CW466, 2) -> 4 | DI466: 45470 | DJ466: 45470 | DK466: 304.35 | DM466: {=INDEX($AW$466:$AW$918, ROWS($AW$466:$AW$918) - ROW() + ROW($AW$466))} -> 44742 | DN466: {=INDEX($AX$466:$AX$918, ROWS($AX$466:$AX$918) - ROW() + ROW($AX$466))} -> 44742 | DO466: {=INDEX($DK$466:$DK$918, ROWS($DK$466:$DK$918) - ROW() + ROW($DK$466))} -> 308.85 | DR466: =WEEKDAY(DM466, 2) -> 4
A467: 45469 | B467: 45470 | C467: 167.1 | E467: {=INDEX($A$466:$A$918, ROWS($A$466:$A$918) - ROW() + ROW($A$466))} -> 44743 | F467: {=INDEX($B$466:$B$918, ROWS($B$466:$B$918) - ROW() + ROW($B$466))} -> 44770 | G467: {=INDEX($C$466:$C$918, ROWS($C$466:$C$918) - ROW() + ROW($C$466))} -> 135 | I467: =((G467-G466)/G466)*100 -> 1.2753188 | J467: =WEEKDAY(E467, 2) -> 5 | L467: =IF(MONTH(F467)<>MONTH(F466), F467, "") -> 44770 | M467: =IF(ISNUMBER(L467), (INDEX(G:G, MATCH(EOMONTH(F467, 0), F:F, 1)) / G467 - 1) * 100, "") -> 19.444444 | N467: 1.8038331 | P467: 18.752307 | Q467: 45469 | R467: 45470 | S467: 39625.1 | U467: {=INDEX($Q$466:$Q$918, ROWS($Q$466:$Q$918) - ROW() + ROW($Q$466))} -> 44743 | V467: {=INDEX($R$466:$R$918, ROWS($R$466:$R$918) - ROW() + ROW($R$466))} -> 44770 | W467: {=INDEX($S$466:$S$918, ROWS($S$466:$S$918) - ROW() + ROW($S$466))} -> 41527.2 | Y467: =((W467-W466)/W466)*100 -> 3.3556128 | Z467: =WEEKDAY(U467, 2) -> 5 | AB467: =IF(MONTH(V467)<>MONTH(V466), V467, "") -> 44770 | AC467: =IF(ISNUMBER(AB467), (INDEX(W:W, MATCH(EOMONTH(V467, 0), V:V, 1)) / W467 - 1) * 100, "") -> 14.644016 | AD467: 3.0107179 | AF467: 18.11977 | AG467: 45469 | AH467: 45470 | AI467: 364.8 | AK467: {=INDEX($AG$466:$AG$918, ROWS($AG$466:$AG$918) - ROW() + ROW($AG$466))} -> 44743 | AL467: {=INDEX($AH$466:$AH$918, ROWS($AH$466:$AH$918) - ROW() + ROW($AH$466))} -> 44770 | AM467: {=INDEX($AI$466:$AI$918, ROWS($AI$466:$AI$918) - ROW() + ROW($AI$466))} -> 140.9 | AO467: =((AM467-AM466)/AM466)*100 -> -1.1574886 | AP467: =WEEKDAY(AK467, 2) -> 5 | AR467: =IF(MONTH(AL467)<>MONTH(AL466), AL467, "") -> 44770 | AS467: =IF(ISNUMBER(AR467), (INDEX(AM:AM, MATCH(EOMONTH(AL467, 0), AL:AL, 1)) / AM467 - 1) * 100, "") -> 6.5649397 | AT467: -1.958307 | AV467: 14.43299 | AW467: 45469 | AX467: 45470 | AY467: 306.45 | BA467: {=INDEX($AW$466:$AW$918, ROWS($AW$466:$AW$918) - ROW() + ROW($AW$466))} -> 44743 | BB467: {=INDEX($AX$466:$AX$918, ROWS($AX$466:$AX$918) - ROW() + ROW($AX$466))} -> 44770 | BC467: {=INDEX($AY$466:$AY$918, ROWS($AY$466:$AY$918) - ROW() + ROW($AY$466))} -> 230.6 | BE467: =((BC467-BC466)/BC466)*100 -> -1.2631128 | BF467: =WEEKDAY(BA467, 2) -> 5 | BH467: =IF(MONTH(BB467)<>MONTH(BB466), BB467, "") -> 44770 | BI467: =IF(ISNUMBER(BH467), (INDEX(BC:BC, MATCH(EOMONTH(BB467, 0), BB:BB, 1)) / BC467 - 1) * 100, "") -> 18.213356 | BJ467: -0.67135051 | BL467: 21.997799 | BM467: 45469 | BN467: 45470 | BO467: 1452 | BQ467: {=INDEX($AW$466:$AW$918, ROWS($AW$466:$AW$918) - ROW() + ROW($AW$466))} -> 44743 | BR467: {=INDEX($AX$466:$AX$918, ROWS($AX$466:$AX$918) - ROW() + ROW($AX$466))} -> 44770 | BS467: {=INDEX($BO$466:$BO$918, ROWS($BO$466:$BO$918) - ROW() + ROW($BO$466))} -> 1101.15 | BU467: =((BS467-BS466)/BS466)*100 -> 1.3856919 | BV467: =WEEKDAY(BQ467, 2) -> 5 | BX467: =IF(MONTH(BR467)<>MONTH(BR466), BR467, "") -> 44770 | BY467: =IF(ISNUMBER(BX467), (INDEX(BS:BS, MATCH(EOMONTH(BR467, 0), BR:BR, 1)) / BS467 - 1) * 100, "") -> 7.7782318 | BZ467: 2.635483 | CB467: -20.372417 | CC467: 45469 | CD467: 45470 | CE467: 1819.75 | CG467: {=INDEX($AW$466:$AW$918, ROWS($AW$466:$AW$918) - ROW() + ROW($AW$466))} -> 44743 | CH467: {=INDEX($AX$466:$AX$918, ROWS($AX$466:$AX$918) - ROW() + ROW($AX$466))} -> 44770 | CI467: {=INDEX($CE$466:$CE$918, ROWS($CE$466:$CE$918) - ROW() + ROW($CE$466))} -> 1328.15 | CK467: =((CI467-CI466)/CI466)*100 -> 3.5715678 | CL467: =WEEKDAY(CG467, 2) -> 5 | CN467: =IF(MONTH(CH467)<>MONTH(CH466), CH467, "") -> 44770 | CO467: =IF(ISNUMBER(CN467), (INDEX(CI:CI, MATCH(EOMONTH(CH467, 0), CH:CH, 1)) / CI467 - 1) * 100, "") -> 19.591161 | CP467: 3.3654033 | CR467: 20.559973 | CS467: 45469 | CT467: 45470 | CU467: 826.35 | CW467: {=INDEX($AW$466:$AW$918, ROWS($AW$466:$AW$918) - ROW() + ROW($AW$466))} -> 44743 | CX467: {=INDEX($AX$466:$AX$918, ROWS($AX$466:$AX$918) - ROW() + ROW($AX$466))} -> 44770 | CY467: {=INDEX($CU$466:$CU$918, ROWS($CU$466:$CU$918) - ROW() + ROW($CU$466))} -> 323.65 | DA467: =((CY467-CY466)/CY466)*100 -> 3.2376396 | DB467: =WEEKDAY(CW467, 2) -> 5 | DD467: =IF(MONTH(CX467)<>MONTH(CX466), CX467, "") -> 44770 | DE467: =IF(ISNUMBER(DD467), (INDEX(CY:CY, MATCH(EOMONTH(CX467, 0), CX:CX, 1)) / CY467 - 1) * 100, "") -> 17.997837 | DF467: 3.3418612 | DH467: 19.4337 | DI467: 45469 | DJ467: 45470 | DK467: 297.85 | DM467: {=INDEX($AW$466:$AW$918, ROWS($AW$466:$AW$918) - ROW() + ROW($AW$466))} -> 44743 | DN467: {=INDEX($AX$466:$AX$918, ROWS($AX$466:$AX$918) - ROW() + ROW($AX$466))} -> 44770 | DO467: {=INDEX($DK$466:$DK$918, ROWS($DK$466:$DK$918) - ROW() + ROW($DK$466))} -> 318.15 | DQ467: =((DO467-DO466)/DO466)*100 -> 3.0111705 | DR467: =WEEKDAY(DM467, 2) -> 5 | DT467: =IF(MONTH(DN467)<>MONTH(DN466), DN467, "") -> 44770 | DU467: =IF(ISNUMBER(DT467), (INDEX(DO:DO, MATCH(EOMONTH(DN467, 0), DN:DN, 1)) / DO467 - 1) * 100, "") -> 2.5145372 | DV467: -14.970179 | DX467: -11.152677
A468: 45468 | B468: 45470 | C468: 167.75 | E468: {=INDEX($A$466:$A$918, ROWS($A$466:$A$918) - ROW() + ROW($A$466))} -> 44746 | F468: {=INDEX($B$466:$B$918, ROWS($B$466:$B$918) - ROW() + ROW($B$466))} -> 44770 | G468: {=INDEX($C$466:$C$918, ROWS($C$466:$C$918) - ROW() + ROW($C$466))} -> 138.8 | I468: =((G468-G467)/G467)*100 -> 2.8148148 | J468: =WEEKDAY(E468, 2) -> 1 | L468: =IF(MONTH(F468)<>MONTH(F467), F468, "") | M468: =IF(ISNUMBER(L468), (INDEX(G:G, MATCH(EOMONTH(F468, 0), F:F, 1)) / G468 - 1) * 100, "") | N468: 2.1410114 | Q468: 45468 | R468: 45470 | S468: 40500.7 | U468: {=INDEX($Q$466:$Q$918, ROWS($Q$466:$Q$918) - ROW() + ROW($Q$466))} -> 44746 | V468: {=INDEX($R$466:$R$918, ROWS($R$466:$R$918) - ROW() + ROW($R$466))} -> 44770 | W468: {=INDEX($S$466:$S$918, ROWS($S$466:$S$918) - ROW() + ROW($S$466))} -> 42075.2 | Y468: =((W468-W467)/W467)*100 -> 1.319617 | Z468: =WEEKDAY(U468, 2) -> 1 | AB468: =IF(MONTH(V468)<>MONTH(V467), V468, "") | AC468: =IF(ISNUMBER(AB468), (INDEX(W:W, MATCH(EOMONTH(V468, 0), V:V, 1)) / W468 - 1) * 100, "") | AD468: 1.6357388 | AG468: 45468 | AH468: 45470 | AI468: 360.2 | AK468: {=INDEX($AG$466:$AG$918, ROWS($AG$466:$AG$918) - ROW() + ROW($AG$466))} -> 44746 | AL468: {=INDEX($AH$466:$AH$918, ROWS($AH$466:$AH$918) - ROW() + ROW($AH$466))} -> 44770 | AM468: {=INDEX($AI$466:$AI$918, ROWS($AI$466:$AI$918) - ROW() + ROW($AI$466))} -> 142.05 | AO468: =((AM468-AM467)/AM467)*100 -> 0.81618169 | AP468: =WEEKDAY(AK468, 2) -> 1 | AR468: =IF(MONTH(AL468)<>MONTH(AL467), AL468, "") | AS468: =IF(ISNUMBER(AR468), (INDEX(AM:AM, MATCH(EOMONTH(AL468, 0), AL:AL, 1)) / AM468 - 1) * 100, "") | AT468: 3.0927835 | AW468: 45468 | AX468: 45470 | AY468: 310 | BA468: {=INDEX($AW$466:$AW$918, ROWS($AW$466:$AW$918) - ROW() + ROW($AW$466))} -> 44746 | BB468: {=INDEX($AX$466:$AX$918, ROWS($AX$466:$AX$918) - ROW() + ROW($AX$466))} -> 44770 | BC468: {=INDEX($AY$466:$AY$918, ROWS($AY$466:$AY$918) - ROW() + ROW($AY$466))} -> 230.7 | BE468: =((BC468-BC467)/BC467)*100 -> 0.043365134 | BF468: =WEEKDAY(BA468, 2) -> 1 | BH468: =IF(MONTH(BB468)<>MONTH(BB467), BB468, "") | BI468: =IF(ISNUMBER(BH468), (INDEX(BC:BC, MATCH(EOMONTH(BB468, 0), BB:BB, 1)) / BC468 - 1) * 100, "") | BJ468: 0.80163471 | BM468: 45468 | BN468: 45470 | BO468: 1461.1 | BQ468: {=INDEX($AW$466:$AW$918, ROWS($AW$466:$AW$918) - ROW() + ROW($AW$466))} -> 44746 | BR468: {=INDEX($AX$466:$AX$918, ROWS($AX$466:$AX$918) - ROW() + ROW($AX$466))} -> 44770 | BS468: {=INDEX($BO$466:$BO$918, ROWS($BO$466:$BO$918) - ROW() + ROW($BO$466))} -> 1119.35 | BU468: =((BS468-BS467)/BS467)*100 -> 1.6528175 | BV468: =WEEKDAY(BQ468, 2) -> 1 | BX468: =IF(MONTH(BR468)<>MONTH(BR467), BR468, "") | BY468: =IF(ISNUMBER(BX468), (INDEX(BS:BS, MATCH(EOMONTH(BR468, 0), BR:BR, 1)) / BS468 - 1) * 100, "") | BZ468: -0.56967945 | CC468: 45468 | CD468: 45470 | CE468: 1815.3 | CG468: {=INDEX($AW$466:$AW$918, ROWS($AW$466:$AW$918) - ROW() + ROW($AW$466))} -> 44746 | CH468: {=INDEX($AX$466:$AX$918, ROWS($AX$466:$AX$918) - ROW() + ROW($AX$466))} -> 44770 | CI468: {=INDEX($CE$466:$CE$918, ROWS($CE$466:$CE$918) - ROW() + ROW($CE$466))} -> 1323.15 | CK468: =((CI468-CI467)/CI467)*100 -> -0.3764635 | CL468: =WEEKDAY(CG468, 2) -> 1 | CN468: =IF(MONTH(CH468)<>MONTH(CH467), CH468, "") | CO468: =IF(ISNUMBER(CN468), (INDEX(CI:CI, MATCH(EOMONTH(CH468, 0), CH:CH, 1)) / CI468 - 1) * 100, "") | CP468: -0.68206655 | CS468: 45468 | CT468: 45470 | CU468: 825.4 | CW468: {=INDEX($AW$466:$AW$918, ROWS($AW$466:$AW$918) - ROW() + ROW($AW$466))} -> 44746 | CX468: {=INDEX($AX$466:$AX$918, ROWS($AX$466:$AX$918) - ROW() + ROW($AX$466))} -> 44770 | CY468: {=INDEX($CU$466:$CU$918, ROWS($CU$466:$CU$918) - ROW() + ROW($CU$466))} -> 325.25 | DA468: =((CY468-CY467)/CY467)*100 -> 0.49436119 | DB468: =WEEKDAY(CW468, 2) -> 1 | DD468: =IF(MONTH(CX468)<>MONTH(CX467), CX468, "") | DE468: =IF(ISNUMBER(DD468), (INDEX(CY:CY, MATCH(EOMONTH(CX468, 0), CX:CX, 1)) / CY468 - 1) * 100, "") | DF468: 0.4951261 | DI468: 45468 | DJ468: 45470 | DK468: 296.45 | DM468: {=INDEX($AW$466:$AW$918, ROWS($AW$466:$AW$918) - ROW() + ROW($AW$466))} -> 44746 | DN468: {=INDEX($AX$466:$AX$918, ROWS($AX$466:$AX$918) - ROW() + ROW($AX$466))} -> 44770 | DO468: {=INDEX($DK$466:$DK$918, ROWS($DK$466:$DK$918) - ROW() + ROW($DK$466))} -> 317.45 | DQ468: =((DO468-DO467)/DO467)*100 -> -0.220022 | DR468: =WEEKDAY(DM468, 2) -> 1 | DT468: =IF(MONTH(DN468)<>MONTH(DN467), DN468, "") | DU468: =IF(ISNUMBER(DT468), (INDEX(DO:DO, MATCH(EOMONTH(DN468, 0), DN:DN, 1)) / DO468 - 1) * 100, "") | DV468: -5.7049334
A469: 45467 | B469: 45470 | C469: 162.2 | E469: {=INDEX($A$466:$A$918, ROWS($A$466:$A$918) - ROW() + ROW($A$466))} -> 44747 | F469: {=INDEX($B$466:$B$918, ROWS($B$466:$B$918) - ROW() + ROW($B$466))} -> 44770 | G469: {=INDEX($C$466:$C$918, ROWS($C$466:$C$918) - ROW() + ROW($C$466))} -> 140 | I469: =((G469-G468)/G468)*100 -> 0.86455331 | J469: =WEEKDAY(E469, 2) -> 2 | L469: =IF(MONTH(F469)<>MONTH(F468), F469, "") | M469: =IF(ISNUMBER(L469), (INDEX(G:G, MATCH(EOMONTH(F469, 0), F:F, 1)) / G469 - 1) * 100, "") | N469: 1.4817492 | Q469: 45467 | R469: 45470 | S469: 40218.25 | U469: {=INDEX($Q$466:$Q$918, ROWS($Q$466:$Q$918) - ROW() + ROW($Q$466))} -> 44747 | V469: {=INDEX($R$466:$R$918, ROWS($R$466:$R$918) - ROW() + ROW($R$466))} -> 44770 | W469: {=INDEX($S$466:$S$918, ROWS($S$466:$S$918) - ROW() + ROW($S$466))} -> 42343.75 | Y469: =((W469-W468)/W468)*100 -> 0.63826197 | Z469: =WEEKDAY(U469, 2) -> 2 | AB469: =IF(MONTH(V469)<>MONTH(V468), V469, "") | AC469: =IF(ISNUMBER(AB469), (INDEX(W:W, MATCH(EOMONTH(V469, 0), V:V, 1)) / W469 - 1) * 100, "") | AD469: 0.70304809 | AG469: 45467 | AH469: 45470 | AI469: 362.9 | AK469: {=INDEX($AG$466:$AG$918, ROWS($AG$466:$AG$918) - ROW() + ROW($AG$466))} -> 44747 | AL469: {=INDEX($AH$466:$AH$918, ROWS($AH$466:$AH$918) - ROW() + ROW($AH$466))} -> 44770 | AM469: {=INDEX($AI$466:$AI$918, ROWS($AI$466:$AI$918) - ROW() + ROW($AI$466))} -> 141.3 | AO469: =((AM469-AM468)/AM468)*100 -> -0.5279831 | AP469: =WEEKDAY(AK469, 2) -> 2 | AR469: =IF(MONTH(AL469)<>MONTH(AL468), AL469, "") | AS469: =IF(ISNUMBER(AR469), (INDEX(AM:AM, MATCH(EOMONTH(AL469, 0), AL:AL, 1)) / AM469 - 1) * 100, "") | AT469: -2.3125 | AW469: 45467 | AX469: 45470 | AY469: 310.25 | BA469: {=INDEX($AW$466:$AW$918, ROWS($AW$466:$AW$918) - ROW() + ROW($AW$466))} -> 44747 | BB469: {=INDEX($AX$466:$AX$918, ROWS($AX$466:$AX$918) - ROW() + ROW($AX$466))} -> 44770 | BC469: {=INDEX($AY$466:$AY$918, ROWS($AY$466:$AY$918) - ROW() + ROW($AY$466))} -> 229.8 | BE469: =((BC469-BC468)/BC468)*100 -> -0.39011704 | BF469: =WEEKDAY(BA469, 2) -> 2 | BH469: =IF(MONTH(BB469)<>MONTH(BB468), BB469, "") | BI469: =IF(ISNUMBER(BH469), (INDEX(BC:BC, MATCH(EOMONTH(BB469, 0), BB:BB, 1)) / BC469 - 1) * 100, "") | BJ469: 2.3935755 | BM469: 45467 | BN469: 45470 | BO469: 1453.65 | BQ469: {=INDEX($AW$466:$AW$918, ROWS($AW$466:$AW$918) - ROW() + ROW($AW$466))} -> 44747 | BR469: {=INDEX($AX$466:$AX$918, ROWS($AX$466:$AX$918) - ROW() + ROW($AX$466))} -> 44770 | BS469: {=INDEX($BO$466:$BO$918, ROWS($BO$466:$BO$918) - ROW() + ROW($BO$466))} -> 1113.45 | BU469: =((BS469-BS468)/BS468)*100 -> -0.52709162 | BV469: =WEEKDAY(BQ469, 2) -> 2 | BX469: =IF(MONTH(BR469)<>MONTH(BR468), BR469, "") | BY469: =IF(ISNUMBER(BX469), (INDEX(BS:BS, MATCH(EOMONTH(BR469, 0), BR:BR, 1)) / BS469 - 1) * 100, "") | BZ469: 0.19668206 | CC469: 45467 | CD469: 45470 | CE469: 1820.15 | CG469: {=INDEX($AW$466:$AW$918, ROWS($AW$466:$AW$918) - ROW() + ROW($AW$466))} -> 44747 | CH469: {=INDEX($AX$466:$AX$918, ROWS($AX$466:$AX$918) - ROW() + ROW($AX$466))} -> 44770 | CI469: {=INDEX($CE$466:$CE$918, ROWS($CE$466:$CE$918) - ROW() + ROW($CE$466))} -> 1305.25 | CK469: =((CI469-CI468)/CI468)*100 -> -1.3528323 | CL469: =WEEKDAY(CG469, 2) -> 2 | CN469: =IF(MONTH(CH469)<>MONTH(CH468), CH469, "") | CO469: =IF(ISNUMBER(CN469), (INDEX(CI:CI, MATCH(EOMONTH(CH469, 0), CH:CH, 1)) / CI469 - 1) * 100, "") | CP469: -1.2027622 | CS469: 45467 | CT469: 45470 | CU469: 840.2 | CW469: {=INDEX($AW$466:$AW$918, ROWS($AW$466:$AW$918) - ROW() + ROW($AW$466))} -> 44747 | CX469: {=INDEX($AX$466:$AX$918, ROWS($AX$466:$AX$918) - ROW() + ROW($AX$466))} -> 44770 | CY469: {=INDEX($CU$466:$CU$918, ROWS($CU$466:$CU$918) - ROW() + ROW($CU$466))} -> 322.9 | DA469: =((CY469-CY468)/CY468)*100 -> -0.72252114 | DB469: =WEEKDAY(CW469, 2) -> 2 | DD469: =IF(MONTH(CX469)<>MONTH(CX468), CX469, "") | DE469: =IF(ISNUMBER(DD469), (INDEX(CY:CY, MATCH(EOMONTH(CX469, 0), CX:CX, 1)) / CY469 - 1) * 100, "") | DF469: -0.81601232 | DI469: 45467 | DJ469: 45470 | DK469: 304.85 | DM469: {=INDEX($AW$466:$AW$918, ROWS($AW$466:$AW$918) - ROW() + ROW($AW$466))} -> 44747 | DN469: {=INDEX($AX$466:$AX$918, ROWS($AX$466:$AX$918) - ROW() + ROW($AX$466))} -> 44770 | DO469: {=INDEX($DK$466:$DK$918, ROWS($DK$466:$DK$918) - ROW() + ROW($DK$466))} -> 314.05 | DQ469: =((DO469-DO468)/DO468)*100 -> -1.0710348 | DR469: =WEEKDAY(DM469, 2) -> 2 | DT469: =IF(MONTH(DN469)<>MONTH(DN468), DN469, "") | DU469: =IF(ISNUMBER(DT469), (INDEX(DO:DO, MATCH(EOMONTH(DN469, 0), DN:DN, 1)) / DO469 - 1) * 100, "") | DV469: -5.4797917
A470: 45464 | B470: 45470 | C470: 162.9 | E470: {=INDEX($A$466:$A$918, ROWS($A$466:$A$918) - ROW() + ROW($A$466))} -> 44748 | F470: {=INDEX($B$466:$B$918, ROWS($B$466:$B$918) - ROW() + ROW($B$466))} -> 44770 | G470: {=INDEX($C$466:$C$918, ROWS($C$466:$C$918) - ROW() + ROW($C$466))} -> 140.65 | I470: =((G470-G469)/G469)*100 -> 0.46428571 | J470: =WEEKDAY(E470, 2) -> 3 | L470: =IF(MONTH(F470)<>MONTH(F469), F470, "") | M470: =IF(ISNUMBER(L470), (INDEX(G:G, MATCH(EOMONTH(F470, 0), F:F, 1)) / G470 - 1) * 100, "") | N470: 0.64102564 | Q470: 45464 | R470: 45470 | S470: 39749.9 | U470: {=INDEX($Q$466:$Q$918, ROWS($Q$466:$Q$918) - ROW() + ROW($Q$466))} -> 44748 | V470: {=INDEX($R$466:$R$918, ROWS($R$466:$R$918) - ROW() + ROW($R$466))} -> 44770 | W470: {=INDEX($S$466:$S$918, ROWS($S$466:$S$918) - ROW() + ROW($S$466))} -> 43589.2 | Y470: =((W470-W469)/W469)*100 -> 2.9412841 | Z470: =WEEKDAY(U470, 2) -> 3 | AB470: =IF(MONTH(V470)<>MONTH(V469), V470, "") | AC470: =IF(ISNUMBER(AB470), (INDEX(W:W, MATCH(EOMONTH(V470, 0), V:V, 1)) / W470 - 1) * 100, "") | AD470: 2.8871323 | AG470: 45464 | AH470: 45470 | AI470: 360.3 | AK470: {=INDEX($AG$466:$AG$918, ROWS($AG$466:$AG$918) - ROW() + ROW($AG$466))} -> 44748 | AL470: {=INDEX($AH$466:$AH$918, ROWS($AH$466:$AH$918) - ROW() + ROW($AH$466))} -> 44770 | AM470: {=INDEX($AI$466:$AI$918, ROWS($AI$466:$AI$918) - ROW() + ROW($AI$466))} -> 138.9 | AO470: =((AM470-AM469)/AM469)*100 -> -1.6985138 | AP470: =WEEKDAY(AK470, 2) -> 3 | AR470: =IF(MONTH(AL470)<>MONTH(AL469), AL470, "") | AS470: =IF(ISNUMBER(AR470), (INDEX(AM:AM, MATCH(EOMONTH(AL470, 0), AL:AL, 1)) / AM470 - 1) * 100, "") | AT470: 0.44785669 | AW470: 45464 | AX470: 45470 | AY470: 305.2 | BA470: {=INDEX($AW$466:$AW$918, ROWS($AW$466:$AW$918) - ROW() + ROW($AW$466))} -> 44748 | BB470: {=INDEX($AX$466:$AX$918, ROWS($AX$466:$AX$918) - ROW() + ROW($AX$466))} -> 44770 | BC470: {=INDEX($AY$466:$AY$918, ROWS($AY$466:$AY$918) - ROW() + ROW($AY$466))} -> 231.3 | BE470: =((BC470-BC469)/BC469)*100 -> 0.65274151 | BF470: =WEEKDAY(BA470, 2) -> 3 | BH470: =IF(MONTH(BB470)<>MONTH(BB469), BB470, "") | BI470: =IF(ISNUMBER(BH470), (INDEX(BC:BC, MATCH(EOMONTH(BB470, 0), BB:BB, 1)) / BC470 - 1) * 100, "") | BJ470: 5.7184192 | BM470: 45464 | BN470: 45470 | BO470: 1464.7 | BQ470: {=INDEX($AW$466:$AW$918, ROWS($AW$466:$AW$918) - ROW() + ROW($AW$466))} -> 44748 | BR470: {=INDEX($AX$466:$AX$918, ROWS($AX$466:$AX$918) - ROW() + ROW($AX$466))} -> 44770 | BS470: {=INDEX($BO$466:$BO$918, ROWS($BO$466:$BO$918) - ROW() + ROW($BO$466))} -> 1120.6 | BU470: =((BS470-BS469)/BS469)*100 -> 0.64214828 | BV470: =WEEKDAY(BQ470, 2) -> 3 | BX470: =IF(MONTH(BR470)<>MONTH(BR469), BR470, "") | BY470: =IF(ISNUMBER(BX470), (INDEX(BS:BS, MATCH(EOMONTH(BR470, 0), BR:BR, 1)) / BS470 - 1) * 100, "") | BZ470: -2.2702057 | CC470: 45464 | CD470: 45470 | CE470: 1817.75 | CG470: {=INDEX($AW$466:$AW$918, ROWS($AW$466:$AW$918) - ROW() + ROW($AW$466))} -> 44748 | CH470: {=INDEX($AX$466:$AX$918, ROWS($AX$466:$AX$918) - ROW() + ROW($AX$466))} -> 44770 | CI470: {=INDEX($CE$466:$CE$918, ROWS($CE$466:$CE$918) - ROW() + ROW($CE$466))} -> 1381.7 | CK470: =((CI470-CI469)/CI469)*100 -> 5.8571155 | CL470: =WEEKDAY(CG470, 2) -> 3 | CN470: =IF(MONTH(CH470)<>MONTH(CH469), CH470, "") | CO470: =IF(ISNUMBER(CN470), (INDEX(CI:CI, MATCH(EOMONTH(CH470, 0), CH:CH, 1)) / CI470 - 1) * 100, "") | CP470: 6.1100657 | CS470: 45464 | CT470: 45470 | CU470: 856.4 | CW470: {=INDEX($AW$466:$AW$918, ROWS($AW$466:$AW$918) - ROW() + ROW($AW$466))} -> 44748 | CX470: {=INDEX($AX$466:$AX$918, ROWS($AX$466:$AX$918) - ROW() + ROW($AX$466))} -> 44770 | CY470: {=INDEX($CU$466:$CU$918, ROWS($CU$466:$CU$918) - ROW() + ROW($CU$466))} -> 330.65 | DA470: =((CY470-CY469)/CY469)*100 -> 2.4001239 | DB470: =WEEKDAY(CW470, 2) -> 3 | DD470: =IF(MONTH(CX470)<>MONTH(CX469), CX470, "") | DE470: =IF(ISNUMBER(DD470), (INDEX(CY:CY, MATCH(EOMONTH(CX470, 0), CX:CX, 1)) / CY470 - 1) * 100, "") | DF470: 2.3284694 | DI470: 45464 | DJ470: 45470 | DK470: 307.35 | DM470: {=INDEX($AW$466:$AW$918, ROWS($AW$466:$AW$918) - ROW() + ROW($AW$466))} -> 44748 | DN470: {=INDEX($AX$466:$AX$918, ROWS($AX$466:$AX$918) - ROW() + ROW($AX$466))} -> 44770 | DO470: {=INDEX($DK$466:$DK$918, ROWS($DK$466:$DK$918) - ROW() + ROW($DK$466))} -> 321.2 | DQ470: =((DO470-DO469)/DO469)*100 -> 2.2767075 | DR470: =WEEKDAY(DM470, 2) -> 3 | DT470: =IF(MONTH(DN470)<>MONTH(DN469), DN470, "") | DU470: =IF(ISNUMBER(DT470), (INDEX(DO:DO, MATCH(EOMONTH(DN470, 0), DN:DN, 1)) / DO470 - 1) * 100, "") | DV470: -8.6044071
A471: 45463 | B471: 45470 | C471: 166.45 | E471: {=INDEX($A$466:$A$918, ROWS($A$466:$A$918) - ROW() + ROW($A$466))} -> 44749 | F471: {=INDEX($B$466:$B$918, ROWS($B$466:$B$918) - ROW() + ROW($B$466))} -> 44770 | G471: {=INDEX($C$466:$C$918, ROWS($C$466:$C$918) - ROW() + ROW($C$466))} -> 145.05 | I471: =((G471-G470)/G470)*100 -> 3.1283327 | J471: =WEEKDAY(E471, 2) -> 4 | K471: =IF(J471=4, ((G471 - G466) / G466)*100, "") -> 8.8147037 | L471: =IF(MONTH(F471)<>MONTH(F470), F471, "") | M471: =IF(ISNUMBER(L471), (INDEX(G:G, MATCH(EOMONTH(F471, 0), F:F, 1)) / G471 - 1) * 100, "") | N471: 2.5831564 | O471: 8.944006 | Q471: 45463 | R471: 45470 | S471: 39536.1 | U471: {=INDEX($Q$466:$Q$918, ROWS($Q$466:$Q$918) - ROW() + ROW($Q$466))} -> 44749 | V471: {=INDEX($R$466:$R$918, ROWS($R$466:$R$918) - ROW() + ROW($R$466))} -> 44770 | W471: {=INDEX($S$466:$S$918, ROWS($S$466:$S$918) - ROW() + ROW($S$466))} -> 44055.55 | Y471: =((W471-W470)/W470)*100 -> 1.0698751 | Z471: =WEEKDAY(U471, 2) -> 4 | AA471: =IF(Z471=4, ((W471 - W466) / W466)*100, "") -> 9.6483358 | AB471: =IF(MONTH(V471)<>MONTH(V470), V471, "") | AC471: =IF(ISNUMBER(AB471), (INDEX(W:W, MATCH(EOMONTH(V471, 0), V:V, 1)) / W471 - 1) * 100, "") | AD471: 1.0176517 | AE471: 9.5796248 | AG471: 45463 | AH471: 45470 | AI471: 358.4 | AK471: {=INDEX($AG$466:$AG$918, ROWS($AG$466:$AG$918) - ROW() + ROW($AG$466))} -> 44749 | AL471: {=INDEX($AH$466:$AH$918, ROWS($AH$466:$AH$918) - ROW() + ROW($AH$466))} -> 44770 | AM471: {=INDEX($AI$466:$AI$918, ROWS($AI$466:$AI$918) - ROW() + ROW($AI$466))} -> 141.1 | AO471: =((AM471-AM470)/AM470)*100 -> 1.5838733 | AP471: =WEEKDAY(AK471, 2) -> 4 | AQ471: =IF(AP471=4, ((AM471 - AM466) / AM466)*100, "") -> -1.017187 | AR471: =IF(MONTH(AL471)<>MONTH(AL470), AL471, "") | AS471: =IF(ISNUMBER(AR471), (INDEX(AM:AM, MATCH(EOMONTH(AL471, 0), AL:AL, 1)) / AM471 - 1) * 100, "") | AT471: 3.2484076 | AU471: 2.4005054 | AW471: 45463 | AX471: 45470 | AY471: 311.75 | BA471: {=INDEX($AW$466:$AW$918, ROWS($AW$466:$AW$918) - ROW() + ROW($AW$466))} -> 44749 | BB471: {=INDEX($AX$466:$AX$918, ROWS($AX$466:$AX$918) - ROW() + ROW($AX$466))} -> 44770 | BC471: {=INDEX($AY$466:$AY$918, ROWS($AY$466:$AY$918) - ROW() + ROW($AY$466))} -> 236.95 | BE471: =((BC471-BC470)/BC470)*100 -> 2.4427151 | BF471: =WEEKDAY(BA471, 2) -> 4 | BG471: =IF(BF471=4, ((BC471 - BC466) / BC466)*100, "") -> 1.4557911 | BH471: =IF(MONTH(BB471)<>MONTH(BB470), BB471, "") | BI471: =IF(ISNUMBER(BH471), (INDEX(BC:BC, MATCH(EOMONTH(BB471, 0), BB:BB, 1)) / BC471 - 1) * 100, "") | BJ471: 0.14405071 | BK471: 8.540203 | BM471: 45463 | BN471: 45470 | BO471: 1458.85 | BQ471: {=INDEX($AW$466:$AW$918, ROWS($AW$466:$AW$918) - ROW() + ROW($AW$466))} -> 44749 | BR471: {=INDEX($AX$466:$AX$918, ROWS($AX$466:$AX$918) - ROW() + ROW($AX$466))} -> 44770 | BS471: {=INDEX($BO$466:$BO$918, ROWS($BO$466:$BO$918) - ROW() + ROW($BO$466))} -> 1129.15 | BU471: =((BS471-BS470)/BS470)*100 -> 0.76298412 | BV471: =WEEKDAY(BQ471, 2) -> 4 | BW471: =IF(BV471=4, ((BS471 - BS466) / BS466)*100, "") -> 3.9637234 | BX471: =IF(MONTH(BR471)<>MONTH(BR470), BR471, "") | BY471: =IF(ISNUMBER(BX471), (INDEX(BS:BS, MATCH(EOMONTH(BR471, 0), BR:BR, 1)) / BS471 - 1) * 100, "") | BZ471: -0.4803074 | CA471: -0.54978619 | CC471: 45463 | CD471: 45470 | CE471: 1864.8 | CG471: {=INDEX($AW$466:$AW$918, ROWS($AW$466:$AW$918) - ROW() + ROW($AW$466))} -> 44749 | CH471: {=INDEX($AX$466:$AX$918, ROWS($AX$466:$AX$918) - ROW() + ROW($AX$466))} -> 44770 | CI471: {=INDEX($CE$466:$CE$918, ROWS($CE$466:$CE$918) - ROW() + ROW($CE$466))} -> 1453.5 | CK471: =((CI471-CI470)/CI470)*100 -> 5.1964971 | CL471: =WEEKDAY(CG471, 2) -> 4 | CM471: =IF(CL471=4, ((CI471 - CI466) / CI466)*100, "") -> 13.34659 | CN471: =IF(MONTH(CH471)<>MONTH(CH470), CH471, "") | CO471: =IF(ISNUMBER(CN471), (INDEX(CI:CI, MATCH(EOMONTH(CH471, 0), CH:CH, 1)) / CI471 - 1) * 100, "") | CP471: 5.1863916 | CQ471: 13.204534 | CS471: 45463 | CT471: 45470 | CU471: 874.55 | CW471: {=INDEX($AW$466:$AW$918, ROWS($AW$466:$AW$918) - ROW() + ROW($AW$466))} -> 44749 | CX471: {=INDEX($AX$466:$AX$918, ROWS($AX$466:$AX$918) - ROW() + ROW($AX$466))} -> 44770 | CY471: {=INDEX($CU$466:$CU$918, ROWS($CU$466:$CU$918) - ROW() + ROW($CU$466))} -> 337.4 | DA471: =((CY471-CY470)/CY470)*100 -> 2.0414335 | DB471: =WEEKDAY(CW471, 2) -> 4 | DC471: =IF(DB471=4, ((CY471 - CY466) / CY466)*100, "") -> 7.6236045 | DD471: =IF(MONTH(CX471)<>MONTH(CX470), CX471, "") | DE471: =IF(ISNUMBER(DD471), (INDEX(CY:CY, MATCH(EOMONTH(CX471, 0), CX:CX, 1)) / CY471 - 1) * 100, "") | DF471: 2.2148058 | DG471: 7.739047 | DI471: 45463 | DJ471: 45470 | DK471: 627.1 | DM471: {=INDEX($AW$466:$AW$918, ROWS($AW$466:$AW$918) - ROW() + ROW($AW$466))} -> 44749 | DN471: {=INDEX($AX$466:$AX$918, ROWS($AX$466:$AX$918) - ROW() + ROW($AX$466))} -> 44770 | DO471: {=INDEX($DK$466:$DK$918, ROWS($DK$466:$DK$918) - ROW() + ROW($DK$466))} -> 328.8 | DQ471: =((DO471-DO470)/DO470)*100 -> 2.366127 | DR471: =WEEKDAY(DM471, 2) -> 4 | DS471: =IF(DR471=4, ((DO471 - DO466) / DO466)*100, "") -> 6.4594463 | DT471: =IF(MONTH(DN471)<>MONTH(DN470), DN471, "") | DU471: =IF(ISNUMBER(DT471), (INDEX(DO:DO, MATCH(EOMONTH(DN471, 0), DN:DN, 1)) / DO471 - 1) * 100, "") | DV471: 1.3490241 | DW471: -29.801193
A472: 45462 | B472: 45470 | C472: 157.5 | E472: {=INDEX($A$466:$A$918, ROWS($A$466:$A$918) - ROW() + ROW($A$466))} -> 44750 | F472: {=INDEX($B$466:$B$918, ROWS($B$466:$B$918) - ROW() + ROW($B$466))} -> 44770 | G472: {=INDEX($C$466:$C$918, ROWS($C$466:$C$918) - ROW() + ROW($C$466))} -> 145.2 | I472: =((G472-G471)/G471)*100 -> 0.10341262 | J472: =WEEKDAY(E472, 2) -> 5 | K472: =IF(J472=4, ((G472 - G467) / G467)*100, "") | L472: =IF(MONTH(F472)<>MONTH(F471), F472, "") | M472: =IF(ISNUMBER(L472), (INDEX(G:G, MATCH(EOMONTH(F472, 0), F:F, 1)) / G472 - 1) * 100, "") | N472: -0.068989307 | Q472: 45462 | R472: 45470 | S472: 38810.45 | U472: {=INDEX($Q$466:$Q$918, ROWS($Q$466:$Q$918) - ROW() + ROW($Q$466))} -> 44750 | V472: {=INDEX($R$466:$R$918, ROWS($R$466:$R$918) - ROW() + ROW($R$466))} -> 44770 | W472: {=INDEX($S$466:$S$918, ROWS($S$466:$S$918) - ROW() + ROW($S$466))} -> 43732.75 | Y472: =((W472-W471)/W471)*100 -> -0.73271132 | Z472: =WEEKDAY(U472, 2) -> 5 | AA472: =IF(Z472=4, ((W472 - W467) / W467)*100, "") | AB472: =IF(MONTH(V472)<>MONTH(V471), V472, "") | AC472: =IF(ISNUMBER(AB472), (INDEX(W:W, MATCH(EOMONTH(V472, 0), V:V, 1)) / W472 - 1) * 100, "") | AD472: -0.99649432 | AG472: 45462 | AH472: 45470 | AI472: 363.2 | AK472: {=INDEX($AG$466:$AG$918, ROWS($AG$466:$AG$918) - ROW() + ROW($AG$466))} -> 44750 | AL472: {=INDEX($AH$466:$AH$918, ROWS($AH$466:$AH$918) - ROW() + ROW($AH$466))} -> 44770 | AM472: {=INDEX($AI$466:$AI$918, ROWS($AI$466:$AI$918) - ROW() + ROW($AI$466))} -> 144.2 | AO472: =((AM472-AM471)/AM471)*100 -> 2.1970234 | AP472: =WEEKDAY(AK472, 2) -> 5 | AQ472: =IF(AP472=4, ((AM472 - AM467) / AM467)*100, "") | AR472: =IF(MONTH(AL472)<>MONTH(AL471), AL472, "") | AS472: =IF(ISNUMBER(AR472), (INDEX(AM:AM, MATCH(EOMONTH(AL472, 0), AL:AL, 1)) / AM472 - 1) * 100, "") | AT472: 1.1104257 | AW472: 45462 | AX472: 45470 | AY472: 309.2 | BA472: {=INDEX($AW$466:$AW$918, ROWS($AW$466:$AW$918) - ROW() + ROW($AW$466))} -> 44750 | BB472: {=INDEX($AX$466:$AX$918, ROWS($AX$466:$AX$918) - ROW() + ROW($AX$466))} -> 44770 | BC472: {=INDEX($AY$466:$AY$918, ROWS($AY$466:$AY$918) - ROW() + ROW($AY$466))} -> 236.8 | BE472: =((BC472-BC471)/BC471)*100 -> -0.063304495 | BF472: =WEEKDAY(BA472, 2) -> 5 | BG472: =IF(BF472=4, ((BC472 - BC467) / BC467)*100, "") | BH472: =IF(MONTH(BB472)<>MONTH(BB471), BB472, "") | BI472: =IF(ISNUMBER(BH472), (INDEX(BC:BC, MATCH(EOMONTH(BB472, 0), BB:BB, 1)) / BC472 - 1) * 100, "") | BJ472: 1.9490794 | BM472: 45462 | BN472: 45470 | BO472: 1448.75 | BQ472: {=INDEX($AW$466:$AW$918, ROWS($AW$466:$AW$918) - ROW() + ROW($AW$466))} -> 44750 | BR472: {=INDEX($AX$466:$AX$918, ROWS($AX$466:$AX$918) - ROW() + ROW($AX$466))} -> 44770 | BS472: {=INDEX($BO$466:$BO$918, ROWS($BO$466:$BO$918) - ROW() + ROW($BO$466))} -> 1147.7 | BU472: =((BS472-BS471)/BS471)*100 -> 1.6428287 | BV472: =WEEKDAY(BQ472, 2) -> 5 | BW472: =IF(BV472=4, ((BS472 - BS467) / BS467)*100, "") | BX472: =IF(MONTH(BR472)<>MONTH(BR471), BR472, "") | BY472: =IF(ISNUMBER(BX472), (INDEX(BS:BS, MATCH(EOMONTH(BR472, 0), BR:BR, 1)) / BS472 - 1) * 100, "") | BZ472: -1.009126 | CC472: 45462 | CD472: 45470 | CE472: 1856.65 | CG472: {=INDEX($AW$466:$AW$918, ROWS($AW$466:$AW$918) - ROW() + ROW($AW$466))} -> 44750 | CH472: {=INDEX($AX$466:$AX$918, ROWS($AX$466:$AX$918) - ROW() + ROW($AX$466))} -> 44770 | CI472: {=INDEX($CE$466:$CE$918, ROWS($CE$466:$CE$918) - ROW() + ROW($CE$466))} -> 1437.1 | CK472: =((CI472-CI471)/CI471)*100 -> -1.128311 | CL472: =WEEKDAY(CG472, 2) -> 5 | CM472: =IF(CL472=4, ((CI472 - CI467) / CI467)*100, "") | CN472: =IF(MONTH(CH472)<>MONTH(CH471), CH472, "") | CO472: =IF(ISNUMBER(CN472), (INDEX(CI:CI, MATCH(EOMONTH(CH472, 0), CH:CH, 1)) / CI472 - 1) * 100, "") | CP472: -1.3419124 | CS472: 45462 | CT472: 45470 | CU472: 859.9 | CW472: {=INDEX($AW$466:$AW$918, ROWS($AW$466:$AW$918) - ROW() + ROW($AW$466))} -> 44750 | CX472: {=INDEX($AX$466:$AX$918, ROWS($AX$466:$AX$918) - ROW() + ROW($AX$466))} -> 44770 | CY472: {=INDEX($CU$466:$CU$918, ROWS($CU$466:$CU$918) - ROW() + ROW($CU$466))} -> 340.75 | DA472: =((CY472-CY471)/CY471)*100 -> 0.99288678 | DB472: =WEEKDAY(CW472, 2) -> 5 | DC472: =IF(DB472=4, ((CY472 - CY467) / CY467)*100, "") | DD472: =IF(MONTH(CX472)<>MONTH(CX471), CX472, "") | DE472: =IF(ISNUMBER(DD472), (INDEX(CY:CY, MATCH(EOMONTH(CX472, 0), CX:CX, 1)) / CY472 - 1) * 100, "") | DF472: 1.0388839 | DI472: 45462 | DJ472: 45470 | DK472: 615.65 | DM472: {=INDEX($AW$466:$AW$918, ROWS($AW$466:$AW$918) - ROW() + ROW($AW$466))} -> 44750 | DN472: {=INDEX($AX$466:$AX$918, ROWS($AX$466:$AX$918) - ROW() + ROW($AX$466))} -> 44770 | DO472: {=INDEX($DK$466:$DK$918, ROWS($DK$466:$DK$918) - ROW() + ROW($DK$466))} -> 326.3 | DQ472: =((DO472-DO471)/DO471)*100 -> -0.76034063 | DR472: =WEEKDAY(DM472, 2) -> 5 | DS472: =IF(DR472=4, ((DO472 - DO467) / DO467)*100, "") | DT472: =IF(MONTH(DN472)<>MONTH(DN471), DN472, "") | DU472: =IF(ISNUMBER(DT472), (INDEX(DO:DO, MATCH(EOMONTH(DN472, 0), DN:DN, 1)) / DO472 - 1) * 100, "") | DV472: 4.3330501
A473: 45461 | B473: 45470 | C473: 157.85 | E473: {=INDEX($A$466:$A$918, ROWS($A$466:$A$918) - ROW() + ROW($A$466))} -> 44753 | F473: {=INDEX($B$466:$B$918, ROWS($B$466:$B$918) - ROW() + ROW($B$466))} -> 44770 | G473: {=INDEX($C$466:$C$918, ROWS($C$466:$C$918) - ROW() + ROW($C$466))} -> 148.7 | I473: =((G473-G472)/G472)*100 -> 2.4104683 | J473: =WEEKDAY(E473, 2) -> 1 | K473: =IF(J473=4, ((G473 - G468) / G468)*100, "") | L473: =IF(MONTH(F473)<>MONTH(F472), F473, "") | M473: =IF(ISNUMBER(L473), (INDEX(G:G, MATCH(EOMONTH(F473, 0), F:F, 1)) / G473 - 1) * 100, "") | N473: 2.9340697 | Q473: 45461 | R473: 45470 | S473: 38517.9 | U473: {=INDEX($Q$466:$Q$918, ROWS($Q$466:$Q$918) - ROW() + ROW($Q$466))} -> 44753 | V473: {=INDEX($R$466:$R$918, ROWS($R$466:$R$918) - ROW() + ROW($R$466))} -> 44770 | W473: {=INDEX($S$466:$S$918, ROWS($S$466:$S$918) - ROW() + ROW($S$466))} -> 43534.7 | Y473: =((W473-W472)/W472)*100 -> -0.45286427 | Z473: =WEEKDAY(U473, 2) -> 1 | AA473: =IF(Z473=4, ((W473 - W468) / W468)*100, "") | AB473: =IF(MONTH(V473)<>MONTH(V472), V473, "") | AC473: =IF(ISNUMBER(AB473), (INDEX(W:W, MATCH(EOMONTH(V473, 0), V:V, 1)) / W473 - 1) * 100, "") | AD473: -0.40527175 | AG473: 45461 | AH473: 45470 | AI473: 370.75 | AK473: {=INDEX($AG$466:$AG$918, ROWS($AG$466:$AG$918) - ROW() + ROW($AG$466))} -> 44753 | AL473: {=INDEX($AH$466:$AH$918, ROWS($AH$466:$AH$918) - ROW() + ROW($AH$466))} -> 44770 | AM473: {=INDEX($AI$466:$AI$918, ROWS($AI$466:$AI$918) - ROW() + ROW($AI$466))} -> 145 | AO473: =((AM473-AM472)/AM472)*100 -> 0.55478502 | AP473: =WEEKDAY(AK473, 2) -> 1 | AQ473: =IF(AP473=4, ((AM473 - AM468) / AM468)*100, "") | AR473: =IF(MONTH(AL473)<>MONTH(AL472), AL473, "") | AS473: =IF(ISNUMBER(AR473), (INDEX(AM:AM, MATCH(EOMONTH(AL473, 0), AL:AL, 1)) / AM473 - 1) * 100, "") | AT473: -0.12202563 | AW473: 45461 | AX473: 45470 | AY473: 319.15 | BA473: {=INDEX($AW$466:$AW$918, ROWS($AW$466:$AW$918) - ROW() + ROW($AW$466))} -> 44753 | BB473: {=INDEX($AX$466:$AX$918, ROWS($AX$466:$AX$918) - ROW() + ROW($AX$466))} -> 44770 | BC473: {=INDEX($AY$466:$AY$918, ROWS($AY$466:$AY$918) - ROW() + ROW($AY$466))} -> 235.6 | BE473: =((BC473-BC472)/BC472)*100 -> -0.50675676 | BF473: =WEEKDAY(BA473, 2) -> 1 | BG473: =IF(BF473=4, ((BC473 - BC468) / BC468)*100, "") | BH473: =IF(MONTH(BB473)<>MONTH(BB472), BB473, "") | BI473: =IF(ISNUMBER(BH473), (INDEX(BC:BC, MATCH(EOMONTH(BB473, 0), BB:BB, 1)) / BC473 - 1) * 100, "") | BJ473: 3.2592593 | BM473: 45461 | BN473: 45470 | BO473: 1473.65 | BQ473: {=INDEX($AW$466:$AW$918, ROWS($AW$466:$AW$918) - ROW() + ROW($AW$466))} -> 44753 | BR473: {=INDEX($AX$466:$AX$918, ROWS($AX$466:$AX$918) - ROW() + ROW($AX$466))} -> 44770 | BS473: {=INDEX($BO$466:$BO$918, ROWS($BO$466:$BO$918) - ROW() + ROW($BO$466))} -> 1148.2 | BU473: =((BS473-BS472)/BS472)*100 -> 0.043565392 | BV473: =WEEKDAY(BQ473, 2) -> 1 | BW473: =IF(BV473=4, ((BS473 - BS468) / BS468)*100, "") | BX473: =IF(MONTH(BR473)<>MONTH(BR472), BR473, "") | BY473: =IF(ISNUMBER(BX473), (INDEX(BS:BS, MATCH(EOMONTH(BR473, 0), BR:BR, 1)) / BS473 - 1) * 100, "") | BZ473: -1.0105487 | CC473: 45461 | CD473: 45470 | CE473: 1889.3 | CG473: {=INDEX($AW$466:$AW$918, ROWS($AW$466:$AW$918) - ROW() + ROW($AW$466))} -> 44753 | CH473: {=INDEX($AX$466:$AX$918, ROWS($AX$466:$AX$918) - ROW() + ROW($AX$466))} -> 44770 | CI473: {=INDEX($CE$466:$CE$918, ROWS($CE$466:$CE$918) - ROW() + ROW($CE$466))} -> 1453.7 | CK473: =((CI473-CI472)/CI472)*100 -> 1.155104 | CL473: =WEEKDAY(CG473, 2) -> 1 | CM473: =IF(CL473=4, ((CI473 - CI468) / CI468)*100, "") | CN473: =IF(MONTH(CH473)<>MONTH(CH472), CH473, "") | CO473: =IF(ISNUMBER(CN473), (INDEX(CI:CI, MATCH(EOMONTH(CH473, 0), CH:CH, 1)) / CI473 - 1) * 100, "") | CP473: 1.1753217 | CS473: 45461 | CT473: 45470 | CU473: 881.05 | CW473: {=INDEX($AW$466:$AW$918, ROWS($AW$466:$AW$918) - ROW() + ROW($AW$466))} -> 44753 | CX473: {=INDEX($AX$466:$AX$918, ROWS($AX$466:$AX$918) - ROW() + ROW($AX$466))} -> 44770 | CY473: {=INDEX($CU$466:$CU$918, ROWS($CU$466:$CU$918) - ROW() + ROW($CU$466))} -> 346.55 | DA473: =((CY473-CY472)/CY472)*100 -> 1.7021277 | DB473: =WEEKDAY(CW473, 2) -> 1 | DC473: =IF(DB473=4, ((CY473 - CY468) / CY468)*100, "") | DD473: =IF(MONTH(CX473)<>MONTH(CX472), CX473, "") | DE473: =IF(ISNUMBER(DD473), (INDEX(CY:CY, MATCH(EOMONTH(CX473, 0), CX:CX, 1)) / CY473 - 1) * 100, "") | DF473: 1.6891892 | DI473: 45461 | DJ473: 45470 | DK473: 631.15 | DM473: {=INDEX($AW$466:$AW$918, ROWS($AW$466:$AW$918) - ROW() + ROW($AW$466))} -> 44753 | DN473: {=INDEX($AX$466:$AX$918, ROWS($AX$466:$AX$918) - ROW() + ROW($AX$466))} -> 44770 | DO473: {=INDEX($DK$466:$DK$918, ROWS($DK$466:$DK$918) - ROW() + ROW($DK$466))} -> 317.1 | DQ473: =((DO473-DO472)/DO472)*100 -> -2.8194913 | DR473: =WEEKDAY(DM473, 2) -> 1 | DS473: =IF(DR473=4, ((DO473 - DO468) / DO468)*100, "") | DT473: =IF(MONTH(DN473)<>MONTH(DN472), DN473, "") | DU473: =IF(ISNUMBER(DT473), (INDEX(DO:DO, MATCH(EOMONTH(DN473, 0), DN:DN, 1)) / DO473 - 1) * 100, "") | DV473: 1.3029316
